<?xml version='1.0'?>

<robot name="robot" xmlns:xacro="http://www.ros.org/wiki/xacro">

  <xacro:property name="chassis_width" value="0.15"/>
  <xacro:property name="chassis_length" value="0.2"/>
  <xacro:property name="chassis_height" value="0.05"/>
  <xacro:property name="chassis_mass" value="0.5"/>
  <xacro:property name="wheel_radius" value="0.04"/>
  <xacro:property name="wheel_width" value="0.03"/>
  <xacro:property name="wheel_mass" value="0.1"/>
  <xacro:property name="axle2axle_dist" value="0.18"/>
  <xacro:property name="camera_link" value="0.05" /> <!-- Size of square 'camera' box -->

  <xacro:include filename="$(find enph353_ros_lab)/urdf/macros.xacro" />


  <link name='chassis'>

    <xacro:box_inertial name="chassis" m="${chassis_mass}" x="${chassis_length}" y="${chassis_width}" z="${chassis_height}"/>

    <collision name='chassis_collision'>
      <geometry>
        <box size="${chassis_length} ${chassis_width} ${chassis_height}"/>
      </geometry>
    </collision>

    <visual name='chassis_visual'>
      <origin xyz="0 0 0" rpy=" 0 0 0"/>
      <geometry>
        <box size="${chassis_length} ${chassis_width} ${chassis_height}"/>
      </geometry>	
    </visual>

  </link>

  <link name='wheel_fr'>

    <xacro:cylinder_inertial name="wheel_fr" m="${wheel_mass}" r="${wheel_radius}" h="${wheel_width}"/>

   <collision>
	<geometry>
		<cylinder length="${wheel_width}" radius="${wheel_radius}"/>
	</geometry>
   </collision>

    <visual name='wheel_fr visual'>
        <origin xyz="0 0 0" rpy="0 0 0"/>
	<geometry>
		<cylinder length="${wheel_width}" radius="${wheel_radius}"/>
	</geometry>
   </visual>
   
  </link>

  <joint name="fr_joint" type="continuous">
	<origin xyz="0.09 0.09 0.0025" rpy="1.5708 0 0"/>
	<parent link="chassis"/>
	<child link="wheel_fr"/>
	<axis xyz=" 0 0 1"/>
  </joint>


  <link name='wheel_fl'>

    <xacro:cylinder_inertial name="wheel_fl" m="${wheel_mass}" r="${wheel_radius}" h="${wheel_width}"/>

   <collision>
	<geometry>
		<cylinder length="${wheel_width}" radius="${wheel_radius}"/>
	</geometry>
   </collision>

    <visual name='wheel_fl visual'>
        <origin xyz="0 0 0" rpy="0 0 0"/>
	<geometry>
		<cylinder length="${wheel_width}" radius="${wheel_radius}"/>
	</geometry>
   </visual>
   
  </link>

  <joint name="fl_joint" type="continuous">
	<origin xyz="0.09 -0.09 0.0025" rpy="-1.5708 0 0"/>
	<parent link="chassis"/>
	<child link="wheel_fl"/>
	<axis xyz=" 0 0 -1"/>
  </joint>

  <link name='wheel_br'>

    <xacro:cylinder_inertial name="wheel_br" m="${wheel_mass}" r="${wheel_radius}" h="${wheel_width}"/>

   <collision>
	<geometry>
		<cylinder length="${wheel_width}" radius="${wheel_radius}"/>
	</geometry>
   </collision>

    <visual name='wheel_br visual'>
        <origin xyz="0 0 0" rpy="0 0 0"/>
	<geometry>
		<cylinder length="${wheel_width}" radius="${wheel_radius}"/>
	</geometry>
   </visual>
   
  </link>

  <joint name="br_joint" type="continuous">
	<origin xyz="-0.09 0.09 0.0025" rpy="1.5708 0 0"/>
	<parent link="chassis"/>
	<child link="wheel_br"/>
	<axis xyz=" 0 0 1"/>
  </joint>

  <link name='wheel_bl'>

    <xacro:cylinder_inertial name="wheel_bl" m="${wheel_mass}" r="${wheel_radius}" h="${wheel_width}"/>

   <collision>
	<geometry>
		<cylinder length="${wheel_width}" radius="${wheel_radius}"/>
	</geometry>
   </collision>

    <visual name='wheel_bl visual'>
        <origin xyz="0 0 0" rpy="0 0 0"/>
	<geometry>
		<cylinder length="${wheel_width}" radius="${wheel_radius}"/>
	</geometry>
   </visual>
   
  </link>

  <joint name="bl_joint" type="continuous">
	<origin xyz="-0.09 -0.09 0.0025" rpy="-1.5708 0 0"/>
	<parent link="chassis"/>
	<child link="wheel_bl"/>
	<axis xyz=" 0 0 -1"/>
  </joint>

<link name="camera_link">
  <collision>
      <origin xyz="0 0 0" rpy="0 0 0"/>
      <geometry>
    <box size="${camera_link} ${camera_link} ${camera_link}"/>
      </geometry>
  </collision>

    <visual>
      <origin xyz="0 0 0" rpy="0 0 0"/>
      <geometry>
    <box size="${camera_link} ${camera_link} ${camera_link}"/>
      </geometry> 
    </visual>

    <inertial>
      <mass value="1e-5" />
      <origin xyz="0 0 0" rpy="0 0 0"/>
      <inertia ixx="1e-6" ixy="0" ixz="0" iyy="1e-6" iyz="0" izz="1e-6" />
    </inertial>
</link>

  <joint name="camera_joint" type="fixed">
    <axis xyz="0 1 0" />
    <origin xyz="0.1 0 0.05" rpy="0 0 0"/>
    <parent link="chassis"/>
    <child link="camera_link"/>
  </joint>

<gazebo reference="camera_link">
	<sensor type="camera" name="camera1">
	 <update_rate> 30.0 </update_rate>
      	 <camera name="head">
        	<horizontal_fov>1.3962634</horizontal_fov>
        	<image>
          		<width>800</width>
          		<height>800</height>
          		<format>R8G8B8</format>
        	</image>
        	<clip>
          		<near>0.02</near>
          		<far>300</far>
        	</clip>
        	<noise>
         		<type>gaussian</type>
          <!-- Noise is sampled independently per pixel on each frame.
               That pixel's noise value is added to each of its color
               channels, which at that point lie in the range [0,1]. -->
          		<mean>0.0</mean>
          		<stddev>0.007</stddev>
        	</noise>
      	</camera>
       <plugin name="camera_controller" filename="libgazebo_ros_camera.so">
        <alwaysOn>true</alwaysOn>
        <updateRate>0.0</updateRate>
        <cameraName>rrbot/camera1</cameraName>
        <imageTopicName>image_raw</imageTopicName>
        <cameraInfoTopicName>camera_info</cameraInfoTopicName>
        <frameName>camera_link</frameName>
        <hackBaseline>0.07</hackBaseline>
        <distortionK1>0.0</distortionK1>
        <distortionK2>0.0</distortionK2>
        <distortionK3>0.0</distortionK3>
        <distortionT1>0.0</distortionT1>
        <distortionT2>0.0</distortionT2>
      </plugin>
    </sensor>

</gazebo>

<gazebo>
  <plugin name="skid_steer_drive_controller" filename="libgazebo_ros_skid_steer_drive.so">
    <updateRate>100.0</updateRate>
    <robotNamespace>/</robotNamespace>
    <leftFrontJoint>fl_joint</leftFrontJoint>
    <rightFrontJoint>fr_joint</rightFrontJoint>
    <leftRearJoint>bl_joint</leftRearJoint>
    <rightRearJoint>br_joint</rightRearJoint>
    <wheelSeparation>0.15</wheelSeparation>
    <wheelDiameter>0.08</wheelDiameter>
    <robotBaseFrame>chassis</robotBaseFrame>
    <torque>20</torque>
    <topicName>cmd_vel</topicName>
    <broadcastTF>false</broadcastTF>
  </plugin>
</gazebo>


</robot>
